[2021-09-16 01:36:56,144] {taskinstance.py:876} INFO - Dependencies all met for <TaskInstance: user_processing.is_api_available 2021-09-16T01:36:55.011278+00:00 [queued]>
[2021-09-16 01:36:56,161] {taskinstance.py:876} INFO - Dependencies all met for <TaskInstance: user_processing.is_api_available 2021-09-16T01:36:55.011278+00:00 [queued]>
[2021-09-16 01:36:56,162] {taskinstance.py:1067} INFO - 
--------------------------------------------------------------------------------
[2021-09-16 01:36:56,162] {taskinstance.py:1068} INFO - Starting attempt 1 of 1
[2021-09-16 01:36:56,163] {taskinstance.py:1069} INFO - 
--------------------------------------------------------------------------------
[2021-09-16 01:36:56,172] {taskinstance.py:1087} INFO - Executing <Task(HttpSensor): is_api_available> on 2021-09-16T01:36:55.011278+00:00
[2021-09-16 01:36:56,175] {standard_task_runner.py:52} INFO - Started process 46763 to run task
[2021-09-16 01:36:56,182] {standard_task_runner.py:76} INFO - Running: ['airflow', 'tasks', 'run', 'user_processing', 'is_api_available', '2021-09-16T01:36:55.011278+00:00', '--job-id', '113', '--pool', 'default_pool', '--raw', '--subdir', 'DAGS_FOLDER/user_processing.py', '--cfg-path', '/tmp/tmpu2mb6mgr', '--error-file', '/tmp/tmpizr33ocs']
[2021-09-16 01:36:56,184] {standard_task_runner.py:77} INFO - Job 113: Subtask is_api_available
[2021-09-16 01:36:56,344] {logging_mixin.py:104} INFO - Running <TaskInstance: user_processing.is_api_available 2021-09-16T01:36:55.011278+00:00 [running]> on host airflowvm
[2021-09-16 01:36:56,514] {taskinstance.py:1280} INFO - Exporting the following env vars:
AIRFLOW_CTX_DAG_OWNER=airflow
AIRFLOW_CTX_DAG_ID=user_processing
AIRFLOW_CTX_TASK_ID=is_api_available
AIRFLOW_CTX_EXECUTION_DATE=2021-09-16T01:36:55.011278+00:00
AIRFLOW_CTX_DAG_RUN_ID=manual__2021-09-16T01:36:55.011278+00:00
[2021-09-16 01:36:56,515] {http.py:101} INFO - Poking: api/
[2021-09-16 01:36:56,548] {taskinstance.py:1481} ERROR - Task failed with exception
Traceback (most recent call last):
  File "/home/airflow/sandbox/lib/python3.8/site-packages/airflow/models/taskinstance.py", line 1137, in _run_raw_task
    self._prepare_and_execute_task_with_callbacks(context, task)
  File "/home/airflow/sandbox/lib/python3.8/site-packages/airflow/models/taskinstance.py", line 1311, in _prepare_and_execute_task_with_callbacks
    result = self._execute_task(context, task_copy)
  File "/home/airflow/sandbox/lib/python3.8/site-packages/airflow/models/taskinstance.py", line 1341, in _execute_task
    result = task_copy.execute(context=context)
  File "/home/airflow/sandbox/lib/python3.8/site-packages/airflow/sensors/base.py", line 226, in execute
    while not self.poke(context):
  File "/home/airflow/sandbox/lib/python3.8/site-packages/airflow/providers/http/sensors/http.py", line 117, in poke
    raise exc
  File "/home/airflow/sandbox/lib/python3.8/site-packages/airflow/providers/http/sensors/http.py", line 103, in poke
    response = self.hook.run(
  File "/home/airflow/sandbox/lib/python3.8/site-packages/airflow/providers/http/hooks/http.py", line 122, in run
    session = self.get_conn(headers)
  File "/home/airflow/sandbox/lib/python3.8/site-packages/airflow/providers/http/hooks/http.py", line 72, in get_conn
    conn = self.get_connection(self.http_conn_id)
  File "/home/airflow/sandbox/lib/python3.8/site-packages/airflow/hooks/base.py", line 67, in get_connection
    conn = Connection.get_connection_from_secrets(conn_id)
  File "/home/airflow/sandbox/lib/python3.8/site-packages/airflow/models/connection.py", line 379, in get_connection_from_secrets
    raise AirflowNotFoundException(f"The conn_id `{conn_id}` isn't defined")
airflow.exceptions.AirflowNotFoundException: The conn_id `user_api` isn't defined
[2021-09-16 01:36:56,554] {taskinstance.py:1524} INFO - Marking task as FAILED. dag_id=user_processing, task_id=is_api_available, execution_date=20210916T013655, start_date=20210916T013656, end_date=20210916T013656
[2021-09-16 01:36:56,594] {local_task_job.py:151} INFO - Task exited with return code 1
