[2021-08-11 00:45:30,434] {taskinstance.py:876} INFO - Dependencies all met for <TaskInstance: elasticsearch_dag.print_es_info 2021-08-10T00:00:00+00:00 [queued]>
[2021-08-11 00:45:30,450] {taskinstance.py:876} INFO - Dependencies all met for <TaskInstance: elasticsearch_dag.print_es_info 2021-08-10T00:00:00+00:00 [queued]>
[2021-08-11 00:45:30,451] {taskinstance.py:1067} INFO - 
--------------------------------------------------------------------------------
[2021-08-11 00:45:30,454] {taskinstance.py:1068} INFO - Starting attempt 1 of 1
[2021-08-11 00:45:30,457] {taskinstance.py:1069} INFO - 
--------------------------------------------------------------------------------
[2021-08-11 00:45:30,466] {taskinstance.py:1087} INFO - Executing <Task(PythonOperator): print_es_info> on 2021-08-10T00:00:00+00:00
[2021-08-11 00:45:30,472] {standard_task_runner.py:52} INFO - Started process 380101 to run task
[2021-08-11 00:45:30,482] {standard_task_runner.py:76} INFO - Running: ['airflow', 'tasks', 'run', 'elasticsearch_dag', 'print_es_info', '2021-08-10T00:00:00+00:00', '--job-id', '102', '--pool', 'default_pool', '--raw', '--subdir', 'DAGS_FOLDER/elasticsearch_dag.py', '--cfg-path', '/tmp/tmp_uwhezhs', '--error-file', '/tmp/tmpmhvf1v3i']
[2021-08-11 00:45:30,483] {standard_task_runner.py:77} INFO - Job 102: Subtask print_es_info
[2021-08-11 00:45:30,658] {logging_mixin.py:104} INFO - Running <TaskInstance: elasticsearch_dag.print_es_info 2021-08-10T00:00:00+00:00 [running]> on host airflowvm
[2021-08-11 00:45:30,798] {taskinstance.py:1280} INFO - Exporting the following env vars:
AIRFLOW_CTX_DAG_OWNER=airflow
AIRFLOW_CTX_DAG_ID=elasticsearch_dag
AIRFLOW_CTX_TASK_ID=print_es_info
AIRFLOW_CTX_EXECUTION_DATE=2021-08-10T00:00:00+00:00
AIRFLOW_CTX_DAG_RUN_ID=scheduled__2021-08-10T00:00:00+00:00
[2021-08-11 00:45:30,799] {taskinstance.py:1481} ERROR - Task failed with exception
Traceback (most recent call last):
  File "/home/airflow/sandbox/lib/python3.8/site-packages/airflow/models/taskinstance.py", line 1137, in _run_raw_task
    self._prepare_and_execute_task_with_callbacks(context, task)
  File "/home/airflow/sandbox/lib/python3.8/site-packages/airflow/models/taskinstance.py", line 1311, in _prepare_and_execute_task_with_callbacks
    result = self._execute_task(context, task_copy)
  File "/home/airflow/sandbox/lib/python3.8/site-packages/airflow/models/taskinstance.py", line 1341, in _execute_task
    result = task_copy.execute(context=context)
  File "/home/airflow/sandbox/lib/python3.8/site-packages/airflow/operators/python.py", line 150, in execute
    return_value = self.execute_callable()
  File "/home/airflow/sandbox/lib/python3.8/site-packages/airflow/operators/python.py", line 161, in execute_callable
    return self.python_callable(*self.op_args, **self.op_kwargs)
  File "/home/airflow/airflow/dags/elasticsearch_dag.py", line 12, in _print_es_info
    hook = ElasticHook()
  File "/home/airflow/airflow/dags/plugins/elasticsearch_plugin/hooks/elastic_hook.py", line 8, in __init__
    super().__ini__(*args, **kwargs)
AttributeError: 'super' object has no attribute '__ini__'
[2021-08-11 00:45:30,804] {taskinstance.py:1524} INFO - Marking task as FAILED. dag_id=elasticsearch_dag, task_id=print_es_info, execution_date=20210810T000000, start_date=20210811T004530, end_date=20210811T004530
[2021-08-11 00:45:30,878] {local_task_job.py:151} INFO - Task exited with return code 1
